<?xml version="1.0"?>
<robot name="amr_robot">

  <material name="blue"><color rgba="0 0 0.8 1"/></material>
  <material name="black"><color rgba="0 0 0 1"/></material>
  <material name="white"><color rgba="1 1 1 1"/></material>
  <material name="red"><color rgba="0.8 0 0 1"/></material>

  <link name="base_footprint"/>
  
  <joint name="base_joint" type="fixed">
    <parent link="base_footprint"/>
    <child link="base_link"/>
    <origin xyz="0 0 0.08"/> 
  </joint>

  <link name="base_link">
    <visual>
      <geometry><box size="0.4 0.3 0.1"/></geometry>
      <material name="blue"/>
    </visual>
    <collision>
      <geometry><box size="0.3 0.2 0.06"/></geometry>
    </collision>
    <inertial>
      <mass value="2.0"/>
      <origin xyz="0 0 0" rpy="0 0 0"/>
      <inertia ixx="0.1" ixy="0" ixz="0" iyy="0.1" iyz="0" izz="0.1"/>
    </inertial>
  </link>

  <link name="left_wheel">
    <visual><geometry><cylinder radius="0.05" length="0.04"/></geometry><material name="black"/></visual>
    <collision><geometry><cylinder radius="0.05" length="0.04"/></geometry></collision>
    <inertial><mass value="0.2"/><inertia ixx="0.001" ixy="0" ixz="0" iyy="0.001" iyz="0" izz="0.001"/></inertial>
  </link>
  <joint name="left_wheel_joint" type="continuous">
    <parent link="base_link"/><child link="left_wheel"/>
    <origin xyz="-0.1 0.17 -0.03" rpy="-1.5708 0 0"/>
    <axis xyz="0 0 1"/>
  </joint>

  <link name="right_wheel">
    <visual><geometry><cylinder radius="0.05" length="0.04"/></geometry><material name="black"/></visual>
    <collision><geometry><cylinder radius="0.05" length="0.04"/></geometry></collision>
    <inertial><mass value="0.2"/><inertia ixx="0.001" ixy="0" ixz="0" iyy="0.001" iyz="0" izz="0.001"/></inertial>
  </link>
  <joint name="right_wheel_joint" type="continuous">
    <parent link="base_link"/><child link="right_wheel"/>
    <origin xyz="-0.1 -0.17 -0.03" rpy="-1.5708 0 0"/>
    <axis xyz="0 0 1"/>
  </joint>

  <link name="caster_wheel">
    <visual><geometry><sphere radius="0.05"/></geometry><material name="black"/></visual>
    <collision><geometry><sphere radius="0.05"/></geometry></collision>
    <inertial><mass value="0.1"/><inertia ixx="0.001" ixy="0" ixz="0" iyy="0.001" iyz="0" izz="0.001"/></inertial>
  </link>
  <joint name="caster_joint" type="fixed">
    <parent link="base_link"/><child link="caster_wheel"/>
    <origin xyz="0.15 0 -0.03"/> 
  </joint>

  <link name="laser_link">
    <visual><geometry><cylinder radius="0.03" length="0.04"/></geometry><material name="black"/></visual>
    <inertial>
      <mass value="0.1"/>
      <inertia ixx="0.001" ixy="0" ixz="0" iyy="0.001" iyz="0" izz="0.001"/>
    </inertial>
  </link>
  <joint name="laser_joint" type="fixed">
    <parent link="base_link"/><child link="laser_link"/><origin xyz="0.1 0 0.07"/>
  </joint>

  <link name="camera_link">
    <visual><geometry><box size="0.02 0.05 0.02"/></geometry><material name="red"/></visual>
    <inertial>
      <mass value="0.05"/>
      <inertia ixx="0.001" ixy="0" ixz="0" iyy="0.001" iyz="0" izz="0.001"/>
    </inertial>
  </link>
  <joint name="camera_joint" type="fixed">
    <parent link="base_link"/><child link="camera_link"/><origin xyz="0.2 0 0.03"/>
  </joint>

  <link name="arm_base_link">
    <visual><geometry><cylinder radius="0.04" length="0.02"/></geometry><material name="white"/></visual>
    <inertial><mass value="0.1"/><inertia ixx="0.001" ixy="0" ixz="0" iyy="0.001" iyz="0" izz="0.001"/></inertial>
  </link>
  <joint name="arm_pivot_joint" type="continuous">
    <parent link="base_link"/><child link="arm_base_link"/><origin xyz="0 0 0.06"/><axis xyz="0 0 1"/>
  </joint>

  <link name="arm_link">
    <visual><origin xyz="0 0 0.1"/><geometry><box size="0.03 0.03 0.2"/></geometry><material name="white"/></visual>
    <collision><origin xyz="0 0 0.1"/><geometry><box size="0.03 0.03 0.2"/></geometry></collision>
    <inertial><mass value="0.2"/><inertia ixx="0.001" ixy="0" ixz="0" iyy="0.001" iyz="0" izz="0.001"/></inertial>
  </link>
  <joint name="arm_lift_joint" type="prismatic">
    <parent link="arm_base_link"/><child link="arm_link"/><origin xyz="0 0 0.01"/><axis xyz="0 0 1"/>
    <limit lower="0" upper="0.15" effort="10" velocity="1.0"/>
  </joint>

  <gazebo reference="left_wheel"><mu1>2.0</mu1><mu2>2.0</mu2><kp>1000000.0</kp><kd>10.0</kd></gazebo>
  <gazebo reference="right_wheel"><mu1>2.0</mu1><mu2>2.0</mu2><kp>1000000.0</kp><kd>10.0</kd></gazebo>
  <gazebo reference="caster_wheel"><mu1>0.0</mu1><mu2>0.0</mu2></gazebo>

  <gazebo>
    <plugin name="diff_drive" filename="libgazebo_ros_diff_drive.so">
      <ros><remapping>cmd_vel:=cmd_vel</remapping><remapping>odom:=odom</remapping></ros>
      <left_joint>left_wheel_joint</left_joint>
      <right_joint>right_wheel_joint</right_joint>
      <wheel_separation>0.34</wheel_separation>
      <wheel_diameter>0.1</wheel_diameter>
      <max_wheel_torque>1000</max_wheel_torque>
      <max_wheel_acceleration>1.0</max_wheel_acceleration>
      <publish_odom>true</publish_odom>
      <publish_odom_tf>true</publish_odom_tf>
      <publish_wheel_tf>true</publish_wheel_tf>
      <odometry_frame>odom</odometry_frame>
      <robot_base_frame>base_footprint</robot_base_frame>
    </plugin>
  </gazebo>

  <gazebo>
    <plugin name="amr_joint_state" filename="libgazebo_ros_joint_state_publisher.so">
      <ros><remapping>~/out:=joint_states</remapping></ros>
      <update_rate>30</update_rate>
      <joint_name>left_wheel_joint</joint_name>
      <joint_name>right_wheel_joint</joint_name>
      <joint_name>arm_pivot_joint</joint_name>
      <joint_name>arm_lift_joint</joint_name>
    </plugin>
  </gazebo>

  <gazebo reference="laser_link">
    <sensor type="ray" name="laser_sensor">
      <visualize>true</visualize><update_rate>10</update_rate>
      <ray>
        <scan><horizontal><samples>360</samples><min_angle>-3.14159</min_angle><max_angle>3.14159</max_angle></horizontal></scan>
        <range><min>0.15</min><max>12.0</max></range>
      </ray>
      <plugin name="laser_controller" filename="libgazebo_ros_ray_sensor.so">
        <ros><remapping>~/out:=scan</remapping></ros>
        <output_type>sensor_msgs/LaserScan</output_type>
        <frame_name>laser_link</frame_name>
      </plugin>
    </sensor>
  </gazebo>

</robot>