<?xml version="1.0"?>
<robot name="amr_robot">

  <material name="blue"><color rgba="0 0 0.8 1"/></material>
  <material name="black"><color rgba="0 0 0 1"/></material>
  <material name="white"><color rgba="1 1 1 1"/></material>
  <material name="red"><color rgba="0.8 0 0 1"/></material>

  <link name="base_footprint"/>
  
  <joint name="base_joint" type="fixed">
    <parent link="base_footprint"/>
    <child link="base_link"/>
    <origin xyz="0 0 0.08"/> 
  </joint>

  <link name="base_link">
    <visual>
      <geometry><box size="0.4 0.3 0.1"/></geometry>
      <material name="blue"/>
    </visual>
    <collision>
      <geometry><box size="0.4 0.3 0.1"/></geometry>
    </collision>
    <inertial>
      <mass value="2.0"/>
      <origin xyz="0 0 0" rpy="0 0 0"/>
      <inertia ixx="0.02" ixy="0" ixz="0" iyy="0.03" iyz="0" izz="0.1"/>
    </inertial>
  </link>

  <!-- 左轮 -->
  <link name="left_wheel">
    <visual><geometry><cylinder radius="0.05" length="0.04"/></geometry><material name="black"/></visual>
    <collision><geometry><cylinder radius="0.05" length="0.04"/></geometry></collision>
    <inertial><mass value="0.2"/><inertia ixx="0.0001" ixy="0" ixz="0" iyy="0.0001" iyz="0" izz="0.0001"/></inertial>
  </link>
  <joint name="left_wheel_joint" type="continuous">
    <parent link="base_link"/>
    <child link="left_wheel"/>
    <origin xyz="-0.1 0.17 -0.03" rpy="-1.5708 0 0"/>
    <axis xyz="0 0 1"/>
  </joint>

  <!-- 右轮 -->
  <link name="right_wheel">
    <visual><geometry><cylinder radius="0.05" length="0.04"/></geometry><material name="black"/></visual>
    <collision><geometry><cylinder radius="0.05" length="0.04"/></geometry></collision>
    <inertial><mass value="0.2"/><inertia ixx="0.0001" ixy="0" ixz="0" iyy="0.0001" iyz="0" izz="0.0001"/></inertial>
  </link>
  <joint name="right_wheel_joint" type="continuous">
    <parent link="base_link"/>
    <child link="right_wheel"/>
    <origin xyz="-0.1 -0.17 -0.03" rpy="-1.5708 0 0"/>
    <axis xyz="0 0 1"/>
  </joint>

  <!-- 万向轮 -->
  <link name="caster_wheel">
    <visual><geometry><sphere radius="0.05"/></geometry><material name="black"/></visual>
    <collision><geometry><sphere radius="0.05"/></geometry></collision>
    <inertial><mass value="0.1"/><inertia ixx="0.0001" ixy="0" ixz="0" iyy="0.0001" iyz="0" izz="0.0001"/></inertial>
  </link>
  <joint name="caster_joint" type="fixed">
    <parent link="base_link"/>
    <child link="caster_wheel"/>
    <origin xyz="0.15 0 -0.03"/> 
  </joint>

  <!-- 雷达 -->
  <link name="laser_link">
    <visual><geometry><cylinder radius="0.03" length="0.04"/></geometry><material name="black"/></visual>
    <inertial><mass value="0.1"/><inertia ixx="0.0001" ixy="0" ixz="0" iyy="0.0001" iyz="0" izz="0.0001"/></inertial>
  </link>
  <joint name="laser_joint" type="fixed">
    <parent link="base_link"/>
    <child link="laser_link"/>
    <origin xyz="0.1 0 0.07" rpy="0 0 0"/>
  </joint>

  <link name="camera_link">
    <visual>
      <geometry><box size="0.04 0.06 0.04"/></geometry>
      <material name="red"/>
    </visual>
    <inertial><mass value="0.05"/><inertia ixx="0.00001" ixy="0" ixz="0" iyy="0.00001" iyz="0" izz="0.00001"/></inertial>
  </link>
  <joint name="camera_joint" type="fixed">
    <parent link="base_link"/>
    <child link="camera_link"/>
    <origin xyz="0.22 0 0.12" rpy="0 0 0"/>
  </joint>

  <!-- 差速驱动（修复：优化高速旋转稳定性） -->
  <gazebo>
    <plugin name="diff_drive" filename="libgazebo_ros_diff_drive.so">
      <ros>
        <remapping>cmd_vel:=cmd_vel</remapping>
        <remapping>odom:=odom</remapping>
      </ros>
      <left_joint>left_wheel_joint</left_joint>
      <right_joint>right_wheel_joint</right_joint>
      <wheel_separation>0.34</wheel_separation>
      <wheel_diameter>0.1</wheel_diameter>
      <update_rate>50</update_rate>
      <!-- 关键修复：降低最大轮速和扭矩，提高旋转稳定性 -->
      <max_wheel_torque>5.0</max_wheel_torque>      <!-- 从20降低到5 -->
      <max_wheel_acceleration>0.5</max_wheel_acceleration>  <!-- 从1.0降低到0.5 -->
      <!-- 新增：速度限制参数 -->
      <max_wheel_velocity>1.0</max_wheel_velocity>   <!-- 限制最大轮速 -->
      <!-- Use Gazebo world odometry in simulation to keep AMCL stable during turns. -->
      <odometry_source>0</odometry_source>           <!-- 1=encoder, 0=Gazebo ground truth -->
      <!-- 新增：减少里程计噪声 -->
      <odometry_rate>20.0</odometry_rate>            <!-- 里程计发布频率 -->
      <publish_odom>true</publish_odom>
      <publish_tf>true</publish_tf>
      <publish_odom_tf>true</publish_odom_tf>
      <publish_wheel_tf>true</publish_wheel_tf>
      <odometry_frame>odom</odometry_frame>
      <robot_base_frame>base_footprint</robot_base_frame>
      <!-- 关键修复：启用TF发布的时间偏移校正 -->
    </plugin>
  </gazebo>

  <!-- 雷达 -->
  <gazebo reference="laser_link">
    <sensor type="ray" name="laser_sensor">
      <visualize>true</visualize>
      <update_rate>10</update_rate>
      <ray>
        <scan>
          <horizontal>
            <samples>360</samples>
            <min_angle>-3.14159</min_angle>
            <max_angle>3.14159</max_angle>
          </horizontal>
        </scan>
        <range>
          <min>0.2</min>
          <max>12.0</max>
        </range>
      </ray>
      <plugin name="laser_controller" filename="libgazebo_ros_ray_sensor.so">
        <ros>
          <remapping>~/out:=scan</remapping>
        </ros>
        <output_type>sensor_msgs/LaserScan</output_type>
        <frame_name>laser_link</frame_name>
      </plugin>
    </sensor>
  </gazebo>

  <gazebo reference="camera_link">
    <sensor type="camera" name="front_camera">
      <visualize>true</visualize>
      <update_rate>15</update_rate>
      <camera>
        <horizontal_fov>1.3962634</horizontal_fov>
        <image>
          <width>640</width>
          <height>480</height>
          <format>R8G8B8</format>
        </image>
        <clip>
          <near>0.05</near>
          <far>8.0</far>
        </clip>
      </camera>
      <plugin name="camera_controller" filename="libgazebo_ros_camera.so">
        <ros>
          <remapping>image_raw:=/camera/image_raw</remapping>
          <remapping>camera_info:=/camera/camera_info</remapping>
        </ros>
        <camera_name>camera</camera_name>
        <frame_name>camera_link</frame_name>
      </plugin>
    </sensor>
  </gazebo>

  <gazebo reference="left_wheel">
    <mu1>1000000.0</mu1>
    <mu2>1000000.0</mu2>
    <kp>1000000.0</kp>
    <kd>10.0</kd>
  </gazebo>
  <gazebo reference="right_wheel">
    <mu1>1000000.0</mu1>
    <mu2>1000000.0</mu2>
    <kp>1000000.0</kp>
    <kd>10.0</kd>
  </gazebo>
  <gazebo reference="caster_wheel">
    <mu1>0.0001</mu1>
    <mu2>0.0001</mu2>
  </gazebo>

</robot>
