<?xml version="1.0"?>
<robot name="amr_robot">

  <material name="blue"><color rgba="0 0 0.8 1"/></material>
  <material name="black"><color rgba="0 0 0 1"/></material>
  <material name="white"><color rgba="1 1 1 1"/></material>
  <material name="red"><color rgba="0.8 0 0 1"/></material>

  <link name="base_footprint"/>
  <joint name="base_joint" type="fixed">
    <parent link="base_footprint"/>
    <child link="base_link"/>
    <origin xyz="0 0 0.05"/>
  </joint>

  <link name="base_link">
    <visual>
      <geometry><box size="0.4 0.3 0.1"/></geometry>
      <material name="blue"/>
    </visual>
    <collision>
      <geometry><box size="0.4 0.3 0.1"/></geometry>
    </collision>
    <inertial>
      <mass value="5.0"/>
      <inertia ixx="0.04" ixy="0" ixz="0" iyy="0.07" iyz="0" izz="0.1"/>
    </inertial>
  </link>

  <link name="left_wheel">
    <visual><geometry><cylinder radius="0.05" length="0.04"/></geometry><material name="black"/></visual>
    <collision><geometry><cylinder radius="0.05" length="0.04"/></geometry></collision>
    <inertial><mass value="0.5"/><inertia ixx="0.001" ixy="0" ixz="0" iyy="0.001" iyz="0" izz="0.001"/></inertial>
  </link>
  <joint name="left_wheel_joint" type="continuous">
    <parent link="base_link"/><child link="left_wheel"/><origin xyz="-0.1 0.17 0" rpy="-1.57 0 0"/><axis xyz="0 0 1"/>
  </joint>

  <link name="right_wheel">
    <visual><geometry><cylinder radius="0.05" length="0.04"/></geometry><material name="black"/></visual>
    <collision><geometry><cylinder radius="0.05" length="0.04"/></geometry></collision>
    <inertial><mass value="0.5"/><inertia ixx="0.001" ixy="0" ixz="0" iyy="0.001" iyz="0" izz="0.001"/></inertial>
  </link>
  <joint name="right_wheel_joint" type="continuous">
    <parent link="base_link"/><child link="right_wheel"/><origin xyz="-0.1 -0.17 0" rpy="-1.57 0 0"/><axis xyz="0 0 1"/>
  </joint>

  <link name="caster_wheel">
    <visual><geometry><sphere radius="0.05"/></geometry><material name="black"/></visual>
    <collision><geometry><sphere radius="0.05"/></geometry></collision>
    <inertial><mass value="0.2"/><inertia ixx="0.0001" ixy="0" ixz="0" iyy="0.0001" iyz="0" izz="0.0001"/></inertial>
  </link>
  <joint name="caster_joint" type="fixed">
    <parent link="base_link"/><child link="caster_wheel"/><origin xyz="0.15 0 -0.01"/>
  </joint>

  <link name="laser_link">
    <visual><geometry><cylinder radius="0.03" length="0.04"/></geometry><material name="black"/></visual>
  </link>
  <joint name="laser_joint" type="fixed">
    <parent link="base_link"/><child link="laser_link"/><origin xyz="0.1 0 0.07"/>
  </joint>

  <link name="camera_link">
    <visual><geometry><box size="0.02 0.05 0.02"/></geometry><material name="red"/></visual>
  </link>
  <joint name="camera_joint" type="fixed">
    <parent link="base_link"/><child link="camera_link"/><origin xyz="0.2 0 0.03"/>
  </joint>

  <link name="arm_base_link">
    <visual><geometry><cylinder radius="0.04" length="0.02"/></geometry><material name="white"/></visual>
  </link>
  <joint name="arm_pivot_joint" type="continuous">
    <parent link="base_link"/><child name="arm_base_link"/><origin xyz="0 0 0.06"/><axis xyz="0 0 1"/>
  </joint>

  <link name="arm_link">
    <visual><origin xyz="0 0 0.1"/><geometry><box size="0.03 0.03 0.2"/></geometry><material name="white"/></visual>
    <collision><origin xyz="0 0 0.1"/><geometry><box size="0.03 0.03 0.2"/></geometry></collision>
  </link>
  <joint name="arm_lift_joint" type="prismatic">
    <parent link="arm_base_link"/><child link="arm_link"/><origin xyz="0 0 0.01"/><axis xyz="0 0 1"/>
    <limit lower="0" upper="0.15" effort="10" velocity="1.0"/>
  </joint>

  <gazebo>
    <plugin name="diff_drive" filename="libgazebo_ros_diff_drive.so">
      <ros><remapping>cmd_vel:=cmd_vel</remapping><remapping>odom:=odom</remapping></ros>
      <left_joint>left_wheel_joint</left_joint>
      <right_joint>right_wheel_joint</right_joint>
      <wheel_separation>0.34</wheel_separation>
      <wheel_diameter>0.1</wheel_diameter>
      <publish_odom>true</publish_odom>
      <publish_odom_tf>true</publish_odom_tf>
      <publish_wheel_tf>true</publish_wheel_tf>
      <odometry_frame>odom</odometry_frame>
      <robot_base_frame>base_footprint</robot_base_frame>
    </plugin>
  </gazebo>

  <gazebo reference="laser_link">
    <sensor type="ray" name="laser_sensor">
      <visualize>true</visualize>
      <update_rate>10</update_rate>
      <ray>
        <scan><horizontal><samples>360</samples><min_angle>-3.14</min_angle><max_angle>3.14</max_angle></horizontal></scan>
        <range><min>0.15</min><max>12.0</max></range>
      </ray>
      <plugin name="laser_controller" filename="libgazebo_ros_ray_sensor.so">
        <ros><remapping>~/out:=scan</remapping></ros>
        <output_type>sensor_msgs/LaserScan</output_type>
        <frame_name>laser_link</frame_name>
      </plugin>
    </sensor>
  </gazebo>

  <gazebo reference="camera_link">
    <sensor type="camera" name="amr_camera">
      <update_rate>30.0</update_rate>
      <camera>
        <horizontal_fov>1.089</horizontal_fov>
        <image><width>640</width><height>480</height><format>R8G8B8</format></image>
        <clip><near>0.05</near><far>8.0</far></clip>
      </camera>
      <plugin name="camera_controller" filename="libgazebo_ros_camera.so">
        <frame_name>camera_link</frame_name>
      </plugin>
    </sensor>
  </gazebo>

</robot>